<?xml version="1.0" encoding="utf-8"?>
<!-- This URDF was automatically created by SolidWorks to URDF Exporter! Originally created by Stephen Brawner (brawner@gmail.com) 
     Commit Version: 1.6.0-4-g7f85cfe  Build Version: 1.6.7995.38578
     For more information, please see http://wiki.ros.org/sw_urdf_exporter -->
<robot
  name="model_1_demo_2">
  <link
    name="base_link">
    <inertial>
      <origin
        xyz="0.00842489194041066 0 0.201251900544968"
        rpy="0 0 0" />
      <mass
        value="13.9592816305195" />
      <inertia
        ixx="0.239628694042062"
        ixy="-6.39036733886322E-11"
        ixz="-0.0223151700721268"
        iyy="0.240967965601768"
        iyz="1.41802447026488E-17"
        izz="0.265624795109163" />
    </inertial>
    <visual>
      <origin
        xyz="0 0 0"
        rpy="0 0 0" />
      <geometry>
        <mesh
          filename="package://model_1_demo_2/meshes/base_link.STL" />
      </geometry>
      <material
        name="">
        <color
          rgba="0.792156862745098 0.819607843137255 0.933333333333333 1" />
      </material>
    </visual>
    <collision>
      <origin
        xyz="0 0 0"
        rpy="0 0 0" />
      <geometry>
        <mesh
          filename="package://model_1_demo_2/meshes/base_link.STL" />
      </geometry>
    </collision>
  </link>
  <link
    name="forwardleft">
    <inertial>
      <origin
        xyz="1.38777878078145E-17 -0.00757672081956784 0"
        rpy="0 0 0" />
      <mass
        value="3.5" />
      <inertia
        ixx="0.00020146248159477"
        ixy="-6.74968403143029E-22"
        ixz="4.19345258499394E-36"
        iyy="0.000395341114732814"
        iyz="0"
        izz="0.00020146248159477" />
    </inertial>
    <visual>
      <origin
        xyz="0 0 0"
        rpy="0 0 0" />
      <geometry>
        <mesh
          filename="package://model_1_demo_2/meshes/forwardleft.STL" />
      </geometry>
      <material
        name="">
        <color
          rgba="0.792156862745098 0.819607843137255 0.933333333333333 1" />
      </material>
    </visual>
    <collision>
      <origin
        xyz="0 0 0"
        rpy="0 0 0" />
      <geometry>
        <mesh
          filename="package://model_1_demo_2/meshes/forwardleft.STL" />
      </geometry>
    </collision>
  </link>
  <joint
    name="leftforjoint"
    type="continuous">
    <origin
      xyz="0.10396 0.1775 0.015"
      rpy="0 0 0" />
    <parent
      link="base_link" />
    <child
      link="forwardleft" />
    <axis
      xyz="0 -1 0" />
    <limit
      effort="1"
      velocity="1" />
  </joint>
  <link
    name="backleft">
    <inertial>
      <origin
        xyz="2.77555756156289E-17 -0.00757672081956784 0"
        rpy="0 0 0" />
      <mass
        value="3.5000" />
      <inertia
        ixx="0.00020146248159477"
        ixy="-6.84894570493665E-22"
        ixz="4.19345258499394E-36"
        iyy="0.000395341114732814"
        iyz="0"
        izz="0.00020146248159477" />
    </inertial>
    <visual>
      <origin
        xyz="0 0 0"
        rpy="0 0 0" />
      <geometry>
        <mesh
          filename="package://model_1_demo_2/meshes/backleft.STL" />
      </geometry>
      <material
        name="">
        <color
          rgba="0.792156862745098 0.819607843137255 0.933333333333333 1" />
      </material>
    </visual>
    <collision>
      <origin
        xyz="0 0 0"
        rpy="0 0 0" />
      <geometry>
        <mesh
          filename="package://model_1_demo_2/meshes/backleft.STL" />
      </geometry>
    </collision>
  </link>
  <joint
    name="leftbackjoint"
    type="continuous">
    <origin
      xyz="-0.096036 0.1775 0.015"
      rpy="0 0 0" />
    <parent
      link="base_link" />
    <child
      link="backleft" />
    <axis
      xyz="0 -1 0" />
    <limit
      effort="1"
      velocity="1" />
  </joint>
  <link
    name="forwardright">
    <inertial>
      <origin
        xyz="-1.73472347597681E-17 0.00757672081956781 0"
        rpy="0 0 0" />
      <mass
        value="3.500" />
      <inertia
        ixx="0.00020146248159477"
        ixy="3.69190351538931E-20"
        ixz="-2.32986567076784E-21"
        iyy="0.000395341114732815"
        iyz="-1.10312717374524E-23"
        izz="0.00020146248159477" />
    </inertial>
    <visual>
      <origin
        xyz="0 0 0"
        rpy="0 0 0" />
      <geometry>
        <mesh
          filename="package://model_1_demo_2/meshes/forwardright.STL" />
      </geometry>
      <material
        name="">
        <color
          rgba="0.792156862745098 0.819607843137255 0.933333333333333 1" />
      </material>
    </visual>
    <collision>
      <origin
        xyz="0 0 0"
        rpy="0 0 0" />
      <geometry>
        <mesh
          filename="package://model_1_demo_2/meshes/forwardright.STL" />
      </geometry>
    </collision>
  </link>
  <joint
    name="rightforjoint"
    type="continuous">
    <origin
      xyz="0.10396 -0.1775 0.015"
      rpy="0 0 0" />
    <parent
      link="base_link" />
    <child
      link="forwardright" />
    <axis
      xyz="0 -1 0" />
    <limit
      effort="1"
      velocity="1" />
  </joint>
  <link
    name="backright">
    <inertial>
      <origin
        xyz="0 0.00757672081956781 0"
        rpy="0 0 0" />
      <mass
        value="3.50000" />
      <inertia
        ixx="0.00020146248159477"
        ixy="3.79751267801208E-20"
        ixz="3.70742350546266E-21"
        iyy="0.000395341114732814"
        iyz="7.94370055212518E-22"
        izz="0.00020146248159477" />
    </inertial>
    <visual>
      <origin
        xyz="0 0 0"
        rpy="0 0 0" />
      <geometry>
        <mesh
          filename="package://model_1_demo_2/meshes/backright.STL" />
      </geometry>
      <material
        name="">
        <color
          rgba="0.792156862745098 0.819607843137255 0.933333333333333 1" />
      </material>
    </visual>
    <collision>
      <origin
        xyz="0 0 0"
        rpy="0 0 0" />
      <geometry>
        <mesh
          filename="package://model_1_demo_2/meshes/backright.STL" />
      </geometry>
    </collision>
  </link>
  <joint
    name="rightbackjoint"
    type="continuous">
    <origin
      xyz="-0.096036 -0.1775 0.015"
      rpy="0 0 0" />
    <parent
      link="base_link" />
    <child
      link="backright" />
    <axis
      xyz="0 -1 0" />
    <limit
      effort="1"
      velocity="1" />
  </joint>
  <link
    name="lidar">
    <inertial>
      <origin
        xyz="0 5.55111512312578E-17 0.0014470438358215"
        rpy="0 0 0" />
      <mass
        value="0.0382236882025974" />
      <inertia
        ixx="1.01480622433405E-05"
        ixy="0"
        ixz="4.54129595568349E-38"
        iyy="1.01480622433405E-05"
        iyz="1.72090096232407E-22"
        izz="1.93916409224957E-05" />
    </inertial>
    <visual>
      <origin
        xyz="0 0 0"
        rpy="0 0 0" />
      <geometry>
        <mesh
          filename="package://model_1_demo_2/meshes/lidar.STL" />
      </geometry>
      <material
        name="">
        <color
          rgba="0.792156862745098 0.819607843137255 0.933333333333333 1" />
      </material>
    </visual>
    <collision>
      <origin
        xyz="0 0 0"
        rpy="0 0 0" />
      <geometry>
        <mesh
          filename="package://model_1_demo_2/meshes/lidar.STL" />
      </geometry>
    </collision>
  </link>
  <joint
    name="lidarfix"
    type="fixed">
    <origin
      xyz="0.086054 0 0.3795"
      rpy="0 0 0" />
    <parent
      link="base_link" />
    <child
      link="lidar" />
    <axis
      xyz="0 0 0" />
  </joint>
  <gazebo reference="lidar">
    <sensor type="ray" name="laser">
        <pose>0 0 0 0 0 0</pose>
        <visualize>true</visualize>
        <update_rate>40</update_rate>
        <ray>
            <scan>
                <horizontal>
                    <samples>720</samples>
                    <resolution>1</resolution>
                    <min_angle>-1.578</min_angle>
                    <max_angle>1.578</max_angle>
                </horizontal>
            </scan>
            <range>
                <min>0.1</min>
                <max>5</max>
                <resolution>0.1</resolution>
            </range>
        </ray>
        <plugin name="Lidar" filename="libgazebo_ros_laser.so">
            <topicName>/scan</topicName>
            <frameName>lidar</frameName>
        </plugin>
    </sensor>
  </gazebo>


    <gazebo>
      <plugin name="skid_steer_drive_controller" filename="libgazebo_ros_skid_steer_drive.so">
          <updateRate>10.0</updateRate>
          <robotNamespace>/</robotNamespace>
          <leftFrontJoint>leftforjoint</leftFrontJoint>
          <rightFrontJoint>rightforjoint</rightFrontJoint>
          <leftRearJoint>leftbackjoint</leftRearJoint>
          <rightRearJoint>rightbackjoint</rightRearJoint>
          <wheelSeparation>0.20792</wheelSeparation>
          <wheelDiameter>0.128</wheelDiameter>
          <robotBaseFrame>base_link</robotBaseFrame>
          <torque>10</torque>
    
          <topicName>cmd_vel</topicName>
          <odometryTopic>odom</odometryTopic>
          <odometryFrame>odom</odometryFrame>
    
          <commandTopic>cmd_vel</commandTopic>
          <topic_name_twist>cmd_vel</topic_name_twist>
          <topic_name_odometry>odom</topic_name_odometry>
          <topic_name_joint>joint</topic_name_joint>
    
          <broadcastTF>true</broadcastTF>
    
          <covariance_x>0.0001</covariance_x>
          <covariance_y>0.0001</covariance_y>
          <covariance_yaw>0.01</covariance_yaw>
    
      </plugin>
    
    </gazebo>
    <!-- <gazebo>
      <plugin name="joint_state_publisher"
              filename="libgazebo_ros_joint_state_publisher.so">
          <jointName>front_caster_of_wheel_joint, front_wheel_joint</jointName>
      </plugin>
    </gazebo> -->





  <gazebo reference="base_link">
      <material>Gazebo/Black</material>
  </gazebo>

  <gazebo reference="lidar">
      <material>Gazebo/Blue</material>
  </gazebo>
    <!-- <gazebo reference="front_wheel">
      <material>Gazebo/Black</material>
    </gazebo>
    <gazebo reference="left_wheel">
      <material>Gazebo/Black</material>
    </gazebo>
    <gazebo reference="right_wheel">
      <material>Gazebo/Black</material>
    </gazebo> -->


</robot>
